Traceback (most recent call last):
  File "D:\Python-API-AutoTest\bz\t_traceback.py", line 4, in <module>
    num=1/0
ZeroDivisionError: division by zero
